Workbook

Sheet 0. README
A1: Section | B1: Content
A2: Model Name | B2: LaunchPlan AI: 24-Month SaaS Operating Model
A3: Purpose | B3: This model helps founders evaluate ARR growth, burn, runway, hiring capacity, unit economics, and fundraising timing.
A4: Business Type | B4: AI SaaS startup
A5: Forecast Period | B5: 24 months
A6: Scenario Logic | B6: Bear, Base, and Bull cases are driven from the Assumptions tab.
A7: Key Outputs | B7: ARR, MRR growth, Gross Margin, CAC Payback, Monthly Burn, Runway, Headcount, and Fundraising Trigger
A8: Main Decision Questions | B8: When should the company hire? When should it preserve cash? When should it begin fundraising?
A9: How to Use | B9: Change assumptions only in the Assumptions tab. Review outputs in Scenarios, Budget vs Actual, and Dashboard.
A10: Dashboard Purpose | B10: The dashboard summarizes the full operating story in one screen for founder-level decision-making.
A12: LaunchPlan AI: 24-Month SaaS Operating Model This workbook is a founder-facing startup finance model built for an early-stage AI SaaS company. The model connects assumptions, revenue growth, churn, headcount planning, COGS, gross margin, unit economics, P&L, cash runway, scenario analysis, budget vs actual tracking, and an executive dashboard. The purpose of the model is not only to forecast financial performance, but to support operating decisions. It helps answer whether the company can afford its hiring plan, whether CAC payback supports GTM expansion, whether gross margin improves toward target, and when fundraising should begin based on runway and burn. The model is structured around a 24-month forecast period with Bear, Base, and Bull case logic. Inputs are managed in the Assumptions tab, while outputs are summarized through Scenarios, Budget vs Actual, and the Dashboard. Key dashboard outputs include ARR, MRR growth, monthly burn, cash runway, gross margin, CAC payback, headcount, and fundraising trigger status.

Sheet 1. Assumptions
A1: LaunchPlan AI — Master Assumptions Tab | FP&A Model | 24-Month Horizon
A2: YELLOW = Hardcoded Input | C2: BLUE = Formula | E2: GREEN = Dashboard Output | H2: RED = Check / Warning
A3: Category | B3: Assumption | C3: Unit | D3: Bear | E3: Base | F3: Bull | G3: Selected Value | H3: Logic / Reasoning | I3: Source / Benchmark | J3: Feeds Into
A4: § 1 CONTROL PANEL
A5: Control Panel | B5: Selected Scenario | C5: Text | G5: Base | H5: Dropdown drives the active model view. Use data validation. | I5: Model design best practice | J5: All tabs
A6: Control Panel | B6: Start Date | C6: Date | D6: 46023 | E6: 46023 | F6: 46023 | G6: =_xlfn.XLOOKUP($G$5,$D$3:$F$3,D6:F6) -> 46023 | H6: Every month offsets from this date via DATE() formulas. Never hardcode month names elsewhere. | I6: Model design best practice | J6: All tabs
A7: Control Panel | B7: Model Horizon | C7: Months | D7: 24 | E7: 24 | F7: 24 | G7: =_xlfn.XLOOKUP($G$5,$D$3:$F$3,D7:F7) -> 24 | H7: 24 months covers Seed-to-Series A without pretending to forecast too far out. | I7: Startup FP&A practice | J7: All tabs
A8: Control Panel | B8: Currency | C8: Text | D8: USD | E8: USD | F8: USD | G8: =_xlfn.XLOOKUP($G$5,$D$3:$F$3,D8:F8) -> USD | H8: Keeps model clean and consistent. | I8: Model design best practice | J8: All tabs
A9: Control Panel | B9: Company Type | C9: Text | D9: AI SaaS | E9: AI SaaS | F9: AI SaaS | G9: =_xlfn.XLOOKUP($G$5,$D$3:$F$3,D9:F9) -> AI SaaS | H9: LaunchPlan AI is an AI-native B2B SaaS company. | I9: Project setup | J9: All tabs
A10: Control Panel | B10: Business Model | C10: Text | D10: Freemium+SaaS+Usage | E10: Freemium+SaaS+Usage | F10: Freemium+SaaS+Usage | G10: =_xlfn.XLOOKUP($G$5,$D$3:$F$3,D10:F10) -> Freemium+SaaS+Usage | H10: Combines Product-led-growth (PLG) acquisition, subscription, and usage-based AI monetization. | I10: AI SaaS / PLG model | J10: Revenue, Unit Economics
A11: § 2 STARTING METRICS
A12: Starting Metrics | B12: Beginning Cash Balance ($) | C12: $ | D12: 1500000 | E12: 1500000 | F12: 1500000 | G12: =_xlfn.XLOOKUP($G$5,$D$3:$F$3,D12:F12) -> 1500000 | H12: Assumes LaunchPlan AI has closed a pre-seed or seed round of ~$1.5M (angel / pre-seed vehicle). | I12: Startup runway practice | J12: Cash, Runway
A13: Starting Metrics | B13: Seed Round Source | C13: Text | D13: Pre-seed/Angel | E13: Pre-seed/Angel | F13: Pre-seed/Angel | G13: =_xlfn.XLOOKUP($G$5,$D$3:$F$3,D13:F13) -> Pre-seed/Angel | H13: NEW: Provides context for starting cash balance. Avoids the cash balance appearing arbitrary. | I13: Startup funding context | J13: Cash, Memo
A14: Starting Metrics | B14: Starting Free Users | C14: Users | D14: 1500 | E14: 2000 | F14: 3000 | G14: =_xlfn.XLOOKUP($G$5,$D$3:$F$3,D14:F14) -> 2000 | H14: Free users create top-of-funnel for PLG conversion. | I14: Freemium SaaS model | J14: Revenue
A15: Starting Metrics | B15: Starting Starter Customers | C15: Customers | D15: 250 | E15: 300 | F15: 400 | G15: =_xlfn.XLOOKUP($G$5,$D$3:$F$3,D15:F15) -> 300 | H15: Starter is the first paid self-serve plan. | I15: Internal model assumption | J15: Revenue
A16: Starting Metrics | B16: Starting Growth Customers | C16: Customers | D16: 140 | E16: 180 | F16: 230 | G16: =_xlfn.XLOOKUP($G$5,$D$3:$F$3,D16:F16) -> 180 | H16: Growth plan is the core early paid customer segment. | I16: Internal model assumption | J16: Revenue
A17: Starting Metrics | B17: Starting Enterprise Customers | C17: Customers | D17: 0 | E17: 0 | F17: 0 | G17: =_xlfn.XLOOKUP($G$5,$D$3:$F$3,D17:F17) -> 0 | H17: Enterprise motion starts after product maturity and initial sales hiring. | I17: Startup GTM logic | J17: Revenue
A18: Starting Metrics | B18: Starting Headcount (FTE) | C18: FTE | D18: 2 | E18: 2 | F18: 2 | G18: =_xlfn.XLOOKUP($G$5,$D$3:$F$3,D18:F18) -> 2 | H18: Founder-led start: CEO and CTO only. | I18: Startup operating practice | J18: Headcount, OpEx
A19: Starting Metrics | B19: Starting MRR ($) | C19: $ | D19: =D15*D23+D16*D24+D17*D25 -> 33110 | E19: =E15*E23+E16*E24+E17*E25 -> 41520 | F19: =F15*F23+F16*F24+F17*F25 -> 53870 | G19: =_xlfn.XLOOKUP($G$5,$D$3:$F$3,D19:F19) -> 41520 | H19: Formula: Starting customers × plan pricing. | I19: Model design best practice | J19: Revenue, ARR
A20: Starting Metrics | B20: Starting ARR ($) | C20: $ | D20: =D19*12 -> 397320 | E20: =E19*12 -> 498240 | F20: =F19*12 -> 646440 | G20: =_xlfn.XLOOKUP($G$5,$D$3:$F$3,D20:F20) -> 498240 | H20: Formula: MRR × 12. | I20: SaaS metric standard | J20: Dashboard
A21: § 3 PRICING & PACKAGING
A22: Pricing | B22: Free Plan Price ($/mo) | C22: $/month | D22: 0 | E22: 0 | F22: 0 | G22: =_xlfn.XLOOKUP($G$5,$D$3:$F$3,D22:F22) -> 0 | H22: Free tier drives PLG top-of-funnel. No direct revenue; acquisition vehicle only. | I22: PLG / freemium practice | J22: Revenue
A23: Pricing | B23: Starter Plan Price ($/mo) | C23: $/month | D23: 49 | E23: 49 | F23: 49 | G23: =_xlfn.XLOOKUP($G$5,$D$3:$F$3,D23:F23) -> 49 | H23: Low-friction founder plan. Price fixed across scenarios ; self-serve pricing should be stable. | I23: SaaS pricing logic | J23: Revenue
A24: Pricing | B24: Growth Plan Price ($/mo) | C24: $/month | D24: 149 | E24: 149 | F24: 149 | G24: =_xlfn.XLOOKUP($G$5,$D$3:$F$3,D24:F24) -> 149 | H24: Core plan for Seed/Series A teams needing recurring FP&A workflows. | I24: SaaS pricing logic | J24: Revenue
A25: Pricing | B25: Enterprise Plan Price ($/mo) | C25: $/month | D25: 499 | E25: 599 | F25: 799 | G25: =_xlfn.XLOOKUP($G$5,$D$3:$F$3,D25:F25) -> 599 | H25: Enterprise flexes because negotiated contracts allow discounting (bear) or premium pricing (bull). | I25: FP&A pricing comps | J25: Revenue
A26: Pricing | B26: Enterprise Implementation Fee ($/logo) | C26: $/logo | D26: 2000 | E26: 3000 | F26: 5000 | G26: =_xlfn.XLOOKUP($G$5,$D$3:$F$3,D26:F26) -> 3000 | H26: One-time onboarding fee for Enterprise setup, integrations, and finance workflow configuration. | I26: FP&A software practice | J26: Other Revenue
A27: Pricing | B27: Implementation Fee Recognition Period | C27: Months | D27: 3 | E27: 3 | F27: 3 | G27: =_xlfn.XLOOKUP($G$5,$D$3:$F$3,D27:F27) -> 3 | H27: Recognize over service delivery period per revenue recognition logic. | I27: Revenue recognition logic | J27: Other Revenue
A28: Pricing | B28: Implementation Fee Included in ARR? | C28: Yes/No | D28: No | E28: No | F28: No | G28: =_xlfn.XLOOKUP($G$5,$D$3:$F$3,D28:F28) -> No | H28: ARR = recurring only. Implementation fees are non-recurring and must be excluded. | I28: SaaS ARR standard | J28: ARR Check
A29: Pricing | B29: Annual Billing Discount | C29: % off monthly | D29: 0.1 | E29: 0.1 | F29: 0.1 | G29: =_xlfn.XLOOKUP($G$5,$D$3:$F$3,D29:F29) -> 0.1 | H29: Annual prepay discount improves cash collection. Standard SaaS practice. | I29: SaaS pricing practice | J29: Cash
A30: Pricing | B30: Annual Billing Mix (% of paid customers) | C30: % of paid | D30: 0.1 | E30: 0.2 | F30: 0.35 | G30: =_xlfn.XLOOKUP($G$5,$D$3:$F$3,D30:F30) -> 0.2 | H30: Bull: more customers commit annually → stronger cash runway. Bear: mostly monthly billing. | I30: SaaS cash collection logic | J30: Cash, Runway
A31: Pricing | B31: Enterprise Payment Terms | C31: Days | D31: 45 | E31: 30 | F31: 30 | G31: =_xlfn.XLOOKUP($G$5,$D$3:$F$3,D31:F31) -> 30 | H31: Enterprise invoices paid slower than self-serve credit card. Bear = slower AR collection. | I31: B2B SaaS practice | J31: Cash
A32: Pricing | B32: Payment Failure / Bad Debt (% of self-serve rev) | C32: % of rev | D32: 0.02 | E32: 0.01 | F32: 0.005 | G32: =_xlfn.XLOOKUP($G$5,$D$3:$F$3,D32:F32) -> 0.01 | H32: Early-stage SMB customers carry payment failure risk. Bear case higher due to weaker ICP fit. | I32: SMB SaaS risk logic | J32: Revenue, Cash
A33: § 4 AI USAGE REVENUE
A34: AI Usage Revenue | B34: AI Overage Price Per Query ($/query) | C34: $/query | D34: 0.08 | E34: 0.1 | F34: 0.15 | G34: =_xlfn.XLOOKUP($G$5,$D$3:$F$3,D34:F34) -> 0.1 | H34: Usage-based pricing captures heavy AI usage above plan limits. Bull = premium pricing. | I34: AI usage pricing logic | J34: Revenue
A35: AI Usage Revenue | B35: Free Plan ; Included Queries/mo | C35: Queries/month | D35: 50 | E35: 50 | F35: 50 | G35: =_xlfn.XLOOKUP($G$5,$D$3:$F$3,D35:F35) -> 50 | H35: Free tier is useful but tightly capped to limit compute cost and push upgrades. | I35: AI cost control logic | J35: Usage Model
A36: AI Usage Revenue | B36: Starter ; Included Queries/mo | C36: Queries/month | D36: 500 | E36: 500 | F36: 500 | G36: =_xlfn.XLOOKUP($G$5,$D$3:$F$3,D36:F36) -> 500 | H36: Supports light founder usage while pushing heavier users to Growth. | I36: Product packaging logic | J36: Usage Model
A37: AI Usage Revenue | B37: Growth ; Included Queries/mo | C37: Queries/month | D37: 2000 | E37: 2000 | F37: 2000 | G37: =_xlfn.XLOOKUP($G$5,$D$3:$F$3,D37:F37) -> 2000 | H37: Core FP&A users need more modeling and reporting prompts. | I37: Product packaging logic | J37: Usage Model
A38: AI Usage Revenue | B38: Enterprise ; Included Queries/mo | C38: Queries/month | D38: 10000 | E38: 12000 | F38: 15000 | G38: =_xlfn.XLOOKUP($G$5,$D$3:$F$3,D38:F38) -> 12000 | H38: Larger teams receive higher usage allowance. Enterprise includes team-wide access. | I38: Enterprise SaaS logic | J38: Usage Model
A39: AI Usage Revenue | B39: AI Usage Revenue Start Month | C39: Month | D39: 14 | E39: 10 | F39: 7 | G39: =_xlfn.XLOOKUP($G$5,$D$3:$F$3,D39:F39) -> 10 | H39: Bull: users hit plan limits earlier due to deeper adoption. Bear: lighter usage depth. | I39: AI adoption logic | J39: Revenue
A40: AI Usage Revenue | B40: Avg Queries Per Active User ; M1 | C40: Queries/month | D40: 40 | E40: 50 | F40: 60 | G40: =_xlfn.XLOOKUP($G$5,$D$3:$F$3,D40:F40) -> 50 | H40: Early usage starts modestly while FP&A workflows are still forming. | I40: Internal usage assumption | J40: Usage Model
...

Sheet 2. Dashboard
J1: LaunchPlanAI Operating Dashboard
A3: Founder Recommendation: Base case supports disciplined GTM and product investment. CAC payback remains inside the hiring gate, gross margin trends toward the target, and runway remains manageable after planned financing. Management should continue hiring selectively, monitor burn and churn closely, and begin fundraising preparation before runway falls below the threshold.
A5: ARR | H5: MRR Growth | O5: Monthly Burn | V5: Cash & Runway
A6: Current ARR and MoM movement | H6: Net new MRR movement | O6: Net cash outflow per month | V6: Cash balance and runway months
A7: =(+'3. Revenue Model'!AA94)/10^6 -> 2.1785868 | H7: =+'3. Revenue Model'!AA97 -> 0.081935207 | L7: =(+'3. Revenue Model'!AA91-'3. Revenue Model'!Z91) -> 13748.741 | O7: =+'7. P&L + cash'!AA81 -> 36838.148 | V7: =+'7. P&L + cash'!AA84 -> 5026732 | Z7: =+'7. P&L + cash'!AA85 -> 136.45453
V10: Financing assumed in Month 23
A15: Gross Margin % | H15: CAC Payback | O15: Headcount by Dept | V15: Fundraising Trigger
A16: Revenue less COGS efficiency | H16: Blended payback in months | O16: Team composition by function | V16: Traffic-light financing signal
A17: =+'7. P&L + cash'!AA37 -> 0.73694968 | H17: =+'6. Unit Economics'!Y61 -> 10.547331 | O17: =+'4. Headcount'!AA64 -> 13 | V17: =IF(Z7<6,"RED",IF(Z7<=12,"AMBER","GREEN")) -> GREEN | Z17: {=_xlfn.SWITCH(V17,"GREEN","Safe: no fundraising action needed","AMBER","Start investor conversations","RED","Raise now","")} -> Safe: no fundraising action needed
O20: R&D | R20: =+'4. Headcount'!AA59 -> 5
O21: Sales & Marketing | R21: =+'4. Headcount'!AA60 -> 4
O22: G&A | R22: =+'4. Headcount'!AA61 -> 2
O23: COGS / Customer Success | R23: =+'4. Headcount'!AA62 -> 2
A26: ARR Movement Bridge | I26: Runway Burn-down | O26: CAC Payback Trend | V26: Gross Margin Expansion | BF26: ARR Movement Bridge | BN26: ARR Movement Bridge | BT26: CAC Payback Trend | CA26: Gross Margin Expansion
BF27: Monthly bridge: new logo MRR + expansion MRR less churn | BN27: Cash balance by scenario with financing threshold overlay | BT27: Blended CAC payback improving against hiring-gate threshold | CA27: Gross margin path showing AI cost leverage and optimization
BF28: Month | BG28: New Logo MRR | BH28: Expansion MRR | BI28: Churn | BJ28: Contraction | BK28: Net MRR Movement | BN28: Month | BO28: Ending Cash | BP28: 6-Month Cash Threshold | BU28: Month | BV28: CAC Payback | BW28: Target | CB28: Month | CC28: Gross Margin % | CD28: M24 Target
BF29: =ROWS($BF$29:BF29) -> 1 | BG29: {=(INDEX('7. P&L + cash'!$D$20:$AA$20,1,$BF29)+INDEX('3. Revenue Model'!$D$64:$AA$64,1,$BF29))*12} -> 30672 | BH29: {=INDEX('7. P&L + cash'!$D$21:$AA$21,1,$BF29)*12} -> 9630 | BI29: {=-INDEX('7. P&L + cash'!$D$23:$AA$23,1,$BF29)*12} -> 0 | BJ29: {=-INDEX('7. P&L + cash'!$D$22:$AA$22,1,$BF29)*12} -> -4982.4 | BK29: {=INDEX('7. P&L + cash'!$D$24:$AA$24,1,$BF29)*12} -> 35319.6 | BN29: =ROWS($BN$29:BN29) -> 1 | BO29: {=INDEX('7. P&L + cash'!$D$84:$AA$84,1,$BN29)} -> 1512335.5 | BP29: {=MAX(0,INDEX('7. P&L + cash'!$D$81:$AA$81,1,$BN29)*6)} -> 0 | BU29: =ROWS($BU$29:BU29) -> 1 | BV29: {=INDEX('6. Unit Economics'!$B$61:$Y$61,1,$BU29)} -> 8.624653 | BW29: ='1. Assumptions'!$G$109 -> 12 | CB29: =ROWS($CB$29:CB29) -> 1 | CC29: {=INDEX('7. P&L + cash'!$D$37:$AA$37,1,$CB29)} -> 0.81985908 | CD29: ='1. Assumptions'!$G$92 -> 0.74
BF30: =ROWS($BF$29:BF30) -> 2 | BG30: {=(INDEX('7. P&L + cash'!$D$20:$AA$20,1,$BF30)+INDEX('3. Revenue Model'!$D$64:$AA$64,1,$BF30))*12} -> 31125.6 | BH30: {=INDEX('7. P&L + cash'!$D$21:$AA$21,1,$BF30)*12} -> 10574.925 | BI30: {=-INDEX('7. P&L + cash'!$D$23:$AA$23,1,$BF30)*12} -> -16372.077 | BJ30: {=-INDEX('7. P&L + cash'!$D$22:$AA$22,1,$BF30)*12} -> -5335.596 | BK30: {=INDEX('7. P&L + cash'!$D$24:$AA$24,1,$BF30)*12} -> 19992.852 | BN30: =ROWS($BN$29:BN30) -> 2 | BO30: {=INDEX('7. P&L + cash'!$D$84:$AA$84,1,$BN30)} -> 1508196.7 | BP30: {=MAX(0,INDEX('7. P&L + cash'!$D$81:$AA$81,1,$BN30)*6)} -> 24832.427 | BU30: =ROWS($BU$29:BU30) -> 2 | BV30: {=INDEX('6. Unit Economics'!$B$61:$Y$61,1,$BU30)} -> 8.8190809 | BW30: ='1. Assumptions'!$G$109 -> 12 | CB30: =ROWS($CB$29:CB30) -> 2 | CC30: {=INDEX('7. P&L + cash'!$D$37:$AA$37,1,$CB30)} -> 0.82012327 | CD30: ='1. Assumptions'!$G$92 -> 0.74
BF31: =ROWS($BF$29:BF31) -> 3 | BG31: {=(INDEX('7. P&L + cash'!$D$20:$AA$20,1,$BF31)+INDEX('3. Revenue Model'!$D$64:$AA$64,1,$BF31))*12} -> 32096.405 | BH31: {=INDEX('7. P&L + cash'!$D$21:$AA$21,1,$BF31)*12} -> 11129.635 | BI31: {=-INDEX('7. P&L + cash'!$D$23:$AA$23,1,$BF31)*12} -> -17141.797 | BJ31: {=-INDEX('7. P&L + cash'!$D$22:$AA$22,1,$BF31)*12} -> -5535.5245 | BK31: {=INDEX('7. P&L + cash'!$D$24:$AA$24,1,$BF31)*12} -> 20548.718 | BN31: =ROWS($BN$29:BN31) -> 3 | BO31: {=INDEX('7. P&L + cash'!$D$84:$AA$84,1,$BN31)} -> 1490023.8 | BP31: {=MAX(0,INDEX('7. P&L + cash'!$D$81:$AA$81,1,$BN31)*6)} -> 109037.83 | BU31: =ROWS($BU$29:BU31) -> 3 | BV31: {=INDEX('6. Unit Economics'!$B$61:$Y$61,1,$BU31)} -> 8.975294 | BW31: ='1. Assumptions'!$G$109 -> 12 | CB31: =ROWS($CB$29:CB31) -> 3 | CC31: {=INDEX('7. P&L + cash'!$D$37:$AA$37,1,$CB31)} -> 0.82048996 | CD31: ='1. Assumptions'!$G$92 -> 0.74
BF32: =ROWS($BF$29:BF32) -> 4 | BG32: {=(INDEX('7. P&L + cash'!$D$20:$AA$20,1,$BF32)+INDEX('3. Revenue Model'!$D$64:$AA$64,1,$BF32))*12} -> 33525.109 | BH32: {=INDEX('7. P&L + cash'!$D$21:$AA$21,1,$BF32)*12} -> 11680.755 | BI32: {=-INDEX('7. P&L + cash'!$D$23:$AA$23,1,$BF32)*12} -> -17925.748 | BJ32: {=-INDEX('7. P&L + cash'!$D$22:$AA$22,1,$BF32)*12} -> -5741.0117 | BK32: {=INDEX('7. P&L + cash'!$D$24:$AA$24,1,$BF32)*12} -> 21539.105 | BN32: =ROWS($BN$29:BN32) -> 4 | BO32: {=INDEX('7. P&L + cash'!$D$84:$AA$84,1,$BN32)} -> 1457902.1 | BP32: {=MAX(0,INDEX('7. P&L + cash'!$D$81:$AA$81,1,$BN32)*6)} -> 192730.07 | BU32: =ROWS($BU$29:BU32) -> 4 | BV32: {=INDEX('6. Unit Economics'!$B$61:$Y$61,1,$BU32)} -> 9.1004172 | BW32: ='1. Assumptions'!$G$109 -> 12 | CB32: =ROWS($CB$29:CB32) -> 4 | CC32: {=INDEX('7. P&L + cash'!$D$37:$AA$37,1,$CB32)} -> 0.82092287 | CD32: ='1. Assumptions'!$G$92 -> 0.74
BF33: =ROWS($BF$29:BF33) -> 5 | BG33: {=(INDEX('7. P&L + cash'!$D$20:$AA$20,1,$BF33)+INDEX('3. Revenue Model'!$D$64:$AA$64,1,$BF33))*12} -> 35370.396 | BH33: {=INDEX('7. P&L + cash'!$D$21:$AA$21,1,$BF33)*12} -> 12246.06 | BI33: {=-INDEX('7. P&L + cash'!$D$23:$AA$23,1,$BF33)*12} -> -18741.374 | BJ33: {=-INDEX('7. P&L + cash'!$D$22:$AA$22,1,$BF33)*12} -> -5956.4027 | BK33: {=INDEX('7. P&L + cash'!$D$24:$AA$24,1,$BF33)*12} -> 22918.678 | BN33: =ROWS($BN$29:BN33) -> 5 | BO33: {=INDEX('7. P&L + cash'!$D$84:$AA$84,1,$BN33)} -> 1416942.8 | BP33: {=MAX(0,INDEX('7. P&L + cash'!$D$81:$AA$81,1,$BN33)*6)} -> 245755.74 | BU33: =ROWS($BU$29:BU33) -> 5 | BV33: {=INDEX('6. Unit Economics'!$B$61:$Y$61,1,$BU33)} -> 9.2013773 | BW33: ='1. Assumptions'!$G$109 -> 12 | CB33: =ROWS($CB$29:CB33) -> 5 | CC33: {=INDEX('7. P&L + cash'!$D$37:$AA$37,1,$CB33)} -> 0.82139574 | CD33: ='1. Assumptions'!$G$92 -> 0.74
BF34: =ROWS($BF$29:BF34) -> 6 | BG34: {=(INDEX('7. P&L + cash'!$D$20:$AA$20,1,$BF34)+INDEX('3. Revenue Model'!$D$64:$AA$64,1,$BF34))*12} -> 44793.441 | BH34: {=INDEX('7. P&L + cash'!$D$21:$AA$21,1,$BF34)*12} -> 12840.678 | BI34: {=-INDEX('7. P&L + cash'!$D$23:$AA$23,1,$BF34)*12} -> -19604.047 | BJ34: {=-INDEX('7. P&L + cash'!$D$22:$AA$22,1,$BF34)*12} -> -6185.5895 | BK34: {=INDEX('7. P&L + cash'!$D$24:$AA$24,1,$BF34)*12} -> 31844.483 | BN34: =ROWS($BN$29:BN34) -> 6 | BO34: {=INDEX('7. P&L + cash'!$D$84:$AA$84,1,$BN34)} -> 1361562.3 | BP34: {=MAX(0,INDEX('7. P&L + cash'!$D$81:$AA$81,1,$BN34)*6)} -> 332282.81 | BU34: =ROWS($BU$29:BU34) -> 6 | BV34: {=INDEX('6. Unit Economics'!$B$61:$Y$61,1,$BU34)} -> 10.30437 | BW34: ='1. Assumptions'!$G$109 -> 12 | CB34: =ROWS($CB$29:CB34) -> 6 | CC34: {=INDEX('7. P&L + cash'!$D$37:$AA$37,1,$CB34)} -> 0.81963945 | CD34: ='1. Assumptions'!$G$92 -> 0.74
BF35: =ROWS($BF$29:BF35) -> 7 | BG35: {=(INDEX('7. P&L + cash'!$D$20:$AA$20,1,$BF35)+INDEX('3. Revenue Model'!$D$64:$AA$64,1,$BF35))*12} -> 47906.385 | BH35: {=INDEX('7. P&L + cash'!$D$21:$AA$21,1,$BF35)*12} -> 13477.82 | BI35: {=-INDEX('7. P&L + cash'!$D$23:$AA$23,1,$BF35)*12} -> -20624.376 | BJ35: {=-INDEX('7. P&L + cash'!$D$22:$AA$22,1,$BF35)*12} -> -6504.0344 | BK35: {=INDEX('7. P&L + cash'!$D$24:$AA$24,1,$BF35)*12} -> 34255.795 | BN35: =ROWS($BN$29:BN35) -> 7 | BO35: {=INDEX('7. P&L + cash'!$D$84:$AA$84,1,$BN35)} -> 1305944.4 | BP35: {=MAX(0,INDEX('7. P&L + cash'!$D$81:$AA$81,1,$BN35)*6)} -> 333707.25 | BU35: =ROWS($BU$29:BU35) -> 7 | BV35: {=INDEX('6. Unit Economics'!$B$61:$Y$61,1,$BU35)} -> 10.315445 | BW35: ='1. Assumptions'!$G$109 -> 12 | CB35: =ROWS($CB$29:CB35) -> 7 | CC35: {=INDEX('7. P&L + cash'!$D$37:$AA$37,1,$CB35)} -> 0.81797357 | CD35: ='1. Assumptions'!$G$92 -> 0.74
BF36: =ROWS($BF$29:BF36) -> 8 | BG36: {=(INDEX('7. P&L + cash'!$D$20:$AA$20,1,$BF36)+INDEX('3. Revenue Model'!$D$64:$AA$64,1,$BF36))*12} -> 51424.026 | BH36: {=INDEX('7. P&L + cash'!$D$21:$AA$21,1,$BF36)*12} -> 14169.345 | BI36: {=-INDEX('7. P&L + cash'!$D$23:$AA$23,1,$BF36)*12} -> -21724.103 | BJ36: {=-INDEX('7. P&L + cash'!$D$22:$AA$22,1,$BF36)*12} -> -6846.5923 | BK36: {=INDEX('7. P&L + cash'!$D$24:$AA$24,1,$BF36)*12} -> 37022.675 | BN36: =ROWS($BN$29:BN36) -> 8 | BO36: {=INDEX('7. P&L + cash'!$D$84:$AA$84,1,$BN36)} -> 1244676.2 | BP36: {=MAX(0,INDEX('7. P&L + cash'!$D$81:$AA$81,1,$BN36)*6)} -> 367609.71 | BU36: =ROWS($BU$29:BU36) -> 8 | BV36: {=INDEX('6. Unit Economics'!$B$61:$Y$61,1,$BU36)} -> 12.392083 | BW36: ='1. Assumptions'!$G$109 -> 12 | CB36: =ROWS($CB$29:CB36) -> 8 | CC36: {=INDEX('7. P&L + cash'!$D$37:$AA$37,1,$CB36)} -> 0.67959487 | CD36: ='1. Assumptions'!$G$92 -> 0.74
BF37: =ROWS($BF$29:BF37) -> 9 | BG37: {=(INDEX('7. P&L + cash'!$D$20:$AA$20,1,$BF37)+INDEX('3. Revenue Model'!$D$64:$AA$64,1,$BF37))*12} -> 55351.782 | BH37: {=INDEX('7. P&L + cash'!$D$21:$AA$21,1,$BF37)*12} -> 14926.223 | BI37: {=-INDEX('7. P&L + cash'!$D$23:$AA$23,1,$BF37)*12} -> -22916.053 | BJ37: {=-INDEX('7. P&L + cash'!$D$22:$AA$22,1,$BF37)*12} -> -7216.8191 | BK37: {=INDEX('7. P&L + cash'!$D$24:$AA$24,1,$BF37)*12} -> 40145.133 | BN37: =ROWS($BN$29:BN37) -> 9 | BO37: {=INDEX('7. P&L + cash'!$D$84:$AA$84,1,$BN37)} -> 1172539.8 | BP37: {=MAX(0,INDEX('7. P&L + cash'!$D$81:$AA$81,1,$BN37)*6)} -> 432818.34 | BU37: =ROWS($BU$29:BU37) -> 9 | BV37: {=INDEX('6. Unit Economics'!$B$61:$Y$61,1,$BU37)} -> 12.200437 | BW37: ='1. Assumptions'!$G$109 -> 12 | CB37: =ROWS($CB$29:CB37) -> 9 | CC37: {=INDEX('7. P&L + cash'!$D$37:$AA$37,1,$CB37)} -> 0.68859869 | CD37: ='1. Assumptions'!$G$92 -> 0.74
BF38: =ROWS($BF$29:BF38) -> 10 | BG38: {=(INDEX('7. P&L + cash'!$D$20:$AA$20,1,$BF38)+INDEX('3. Revenue Model'!$D$64:$AA$64,1,$BF38))*12} -> 59702.306 | BH38: {=INDEX('7. P&L + cash'!$D$21:$AA$21,1,$BF38)*12} -> 15758.913 | BI38: {=-INDEX('7. P&L + cash'!$D$23:$AA$23,1,$BF38)*12} -> -24212.872 | BJ38: {=-INDEX('7. P&L + cash'!$D$22:$AA$22,1,$BF38)*12} -> -7618.2704 | BK38: {=INDEX('7. P&L + cash'!$D$24:$AA$24,1,$BF38)*12} -> 43630.076 | BN38: =ROWS($BN$29:BN38) -> 10 | BO38: {=INDEX('7. P&L + cash'!$D$84:$AA$84,1,$BN38)} -> 1090493.4 | BP38: {=MAX(0,INDEX('7. P&L + cash'!$D$81:$AA$81,1,$BN38)*6)} -> 492278.33 | BU38: =ROWS($BU$29:BU38) -> 10 | BV38: {=INDEX('6. Unit Economics'!$B$61:$Y$61,1,$BU38)} -> 11.968758 | BW38: ='1. Assumptions'!$G$109 -> 12 | CB38: =ROWS($CB$29:CB38) -> 10 | CC38: {=INDEX('7. P&L + cash'!$D$37:$AA$37,1,$CB38)} -> 0.6972596 | CD38: ='1. Assumptions'!$G$92 -> 0.74
BF39: =ROWS($BF$29:BF39) -> 11 | BG39: {=(INDEX('7. P&L + cash'!$D$20:$AA$20,1,$BF39)+INDEX('3. Revenue Model'!$D$64:$AA$64,1,$BF39))*12} -> 64494.672 | BH39: {=INDEX('7. P&L + cash'!$D$21:$AA$21,1,$BF39)*12} -> 16677.662 | BI39: {=-INDEX('7. P&L + cash'!$D$23:$AA$23,1,$BF39)*12} -> -25627.314 | BJ39: {=-INDEX('7. P&L + cash'!$D$22:$AA$22,1,$BF39)*12} -> -8054.5711 | BK39: {=INDEX('7. P&L + cash'!$D$24:$AA$24,1,$BF39)*12} -> 47490.449 | BN39: =ROWS($BN$29:BN39) -> 11 | BO39: {=INDEX('7. P&L + cash'!$D$84:$AA$84,1,$BN39)} -> 1011976.8 | BP39: {=MAX(0,INDEX('7. P&L + cash'!$D$81:$AA$81,1,$BN39)*6)} -> 471099.56 | BU39: =ROWS($BU$29:BU39) -> 11 | BV39: {=INDEX('6. Unit Economics'!$B$61:$Y$61,1,$BU39)} -> 11.749603 | BW39: ='1. Assumptions'!$G$109 -> 12 | CB39: =ROWS($CB$29:CB39) -> 11 | CC39: {=INDEX('7. P&L + cash'!$D$37:$AA$37,1,$CB39)} -> 0.70557352 | CD39: ='1. Assumptions'!$G$92 -> 0.74
BF40: =ROWS($BF$29:BF40) -> 12 | BG40: {=(INDEX('7. P&L + cash'!$D$20:$AA$20,1,$BF40)+INDEX('3. Revenue Model'!$D$64:$AA$64,1,$BF40))*12} -> 69753.801 | BH40: {=INDEX('7. P&L + cash'!$D$21:$AA$21,1,$BF40)*12} -> 17692.772 | BI40: {=-INDEX('7. P&L + cash'!$D$23:$AA$23,1,$BF40)*12} -> -27172.485 | BJ40: {=-INDEX('7. P&L + cash'!$D$22:$AA$22,1,$BF40)*12} -> -8529.4756 | BK40: {=INDEX('7. P&L + cash'!$D$24:$AA$24,1,$BF40)*12} -> 51744.612 | BN40: =ROWS($BN$29:BN40) -> 12 | BO40: {=INDEX('7. P&L + cash'!$D$84:$AA$84,1,$BN40)} -> 923184.26 | BP40: {=MAX(0,INDEX('7. P&L + cash'!$D$81:$AA$81,1,$BN40)*6)} -> 532755.13 | BU40: =ROWS($BU$29:BU40) -> 12 | BV40: {=INDEX('6. Unit Economics'!$B$61:$Y$61,1,$BU40)} -> 11.543814 | BW40: ='1. Assumptions'!$G$109 -> 12 | CB40: =ROWS($CB$29:CB40) -> 12 | CC40: {=INDEX('7. P&L + cash'!$D$37:$AA$37,1,$CB40)} -> 0.71353776 | CD40: ='1. Assumptions'!$G$92 -> 0.74
... BF43: =ROWS($BF$29:BF43) -> 15 | BG43: {=(INDEX('7. P&L + cash'!$D$20:$AA$20,1,$BF43)+INDEX('3. Revenue Model'!$D$64:$AA$64,1,$BF43))*12} -> 88662.238 | BH43: {=INDEX('7. P&L + cash'!$D$21:$AA$21,1,$BF43)*12} -> 21424.523 | BI43: {=-INDEX('7. P&L + cash'!$D$23:$AA$23,1,$BF43)*12} -> -32733.174 | BJ43: {=-INDEX('7. P&L + cash'!$D$22:$AA$22,1,$BF43)*12} -> -10226.406 | BK43: {=INDEX('7. P&L + cash'!$D$24:$AA$24,1,$BF43)*12} -> 67127.181 | BN43: =ROWS($BN$29:BN43) -> 15 | BO43: {=INDEX('7. P&L + cash'!$D$84:$AA$84,1,$BN43)} -> 652994.09 | BP43: {=MAX(0,INDEX('7. P&L + cash'!$D$81:$AA$81,1,$BN43)*6)} -> 538442.06 | BU43: =ROWS($BU$29:BU43) -> 15 | BV43: {=INDEX('6. Unit Economics'!$B$61:$Y$61,1,$BU43)} -> 11.005965 | BW43: ='1. Assumptions'!$G$109 -> 12 | CB43: =ROWS($CB$29:CB43) -> 15 | CC43: {=INDEX('7. P&L + cash'!$D$37:$AA$37,1,$CB43)} -> 0.73530847 | CD43: ='1. Assumptions'!$G$92 -> 0.74
U44: Gross margin path showing AI cost leverage and optimization | BF44: =ROWS($BF$29:BF44) -> 16 | BG44: {=(INDEX('7. P&L + cash'!$D$20:$AA$20,1,$BF44)+INDEX('3. Revenue Model'!$D$64:$AA$64,1,$BF44))*12} -> 96145.216 | BH44: {=INDEX('7. P&L + cash'!$D$21:$AA$21,1,$BF44)*12} -> 22936.361 | BI44: {=-INDEX('7. P&L + cash'!$D$23:$AA$23,1,$BF44)*12} -> -34946.631 | BJ44: {=-INDEX('7. P&L + cash'!$D$22:$AA$22,1,$BF44)*12} -> -10897.678 | BK44: {=INDEX('7. P&L + cash'!$D$24:$AA$24,1,$BF44)*12} -> 73237.268 | BN44: =ROWS($BN$29:BN44) -> 16 | BO44: {=INDEX('7. P&L + cash'!$D$84:$AA$84,1,$BN44)} -> 560318.8 | BP44: {=MAX(0,INDEX('7. P&L + cash'!$D$81:$AA$81,1,$BN44)*6)} -> 556051.78 | BU44: =ROWS($BU$29:BU44) -> 16 | BV44: {=INDEX('6. Unit Economics'!$B$61:$Y$61,1,$BU44)} -> 12.206202 | BW44: ='1. Assumptions'!$G$109 -> 12 | CB44: =ROWS($CB$29:CB44) -> 16 | CC44: {=INDEX('7. P&L + cash'!$D$37:$AA$37,1,$CB44)} -> 0.65950822 | CD44: ='1. Assumptions'!$G$92 -> 0.74
BF45: =ROWS($BF$29:BF45) -> 17 | BG45: {=(INDEX('7. P&L + cash'!$D$20:$AA$20,1,$BF45)+INDEX('3. Revenue Model'!$D$64:$AA$64,1,$BF45))*12} -> 104299.87 | BH45: {=INDEX('7. P&L + cash'!$D$21:$AA$21,1,$BF45)*12} -> 24603.805 | BI45: {=-INDEX('7. P&L + cash'!$D$23:$AA$23,1,$BF45)*12} -> -37368.695 | BJ45: {=-INDEX('7. P&L + cash'!$D$22:$AA$22,1,$BF45)*12} -> -11630.051 | BK45: {=INDEX('7. P&L + cash'!$D$24:$AA$24,1,$BF45)*12} -> 79904.928 | BN45: =ROWS($BN$29:BN45) -> 17 | BO45: {=INDEX('7. P&L + cash'!$D$84:$AA$84,1,$BN45)} -> 473952.43 | BP45: {=MAX(0,INDEX('7. P&L + cash'!$D$81:$AA$81,1,$BN45)*6)} -> 518198.18 | BU45: =ROWS($BU$29:BU45) -> 17 | BV45: {=INDEX('6. Unit Economics'!$B$61:$Y$61,1,$BU45)} -> 11.93168 | BW45: ='1. Assumptions'!$G$109 -> 12 | CB45: =ROWS($CB$29:CB45) -> 17 | CC45: {=INDEX('7. P&L + cash'!$D$37:$AA$37,1,$CB45)} -> 0.67130608 | CD45: ='1. Assumptions'!$G$92 -> 0.74
BF46: =ROWS($BF$29:BF46) -> 18 | BG46: {=(INDEX('7. P&L + cash'!$D$20:$AA$20,1,$BF46)+INDEX('3. Revenue Model'!$D$64:$AA$64,1,$BF46))*12} -> 113183.55 | BH46: {=INDEX('7. P&L + cash'!$D$21:$AA$21,1,$BF46)*12} -> 26441.429 | BI46: {=-INDEX('7. P&L + cash'!$D$23:$AA$23,1,$BF46)*12} -> -40018.678 | BJ46: {=-INDEX('7. P&L + cash'!$D$22:$AA$22,1,$BF46)*12} -> -12429.1 | BK46: {=INDEX('7. P&L + cash'!$D$24:$AA$24,1,$BF46)*12} -> 87177.204 | BN46: =ROWS($BN$29:BN46) -> 18 | BO46: {=INDEX('7. P&L + cash'!$D$84:$AA$84,1,$BN46)} -> 394527.59 | BP46: {=MAX(0,INDEX('7. P&L + cash'!$D$81:$AA$81,1,$BN46)*6)} -> 476549.02 | BU46: =ROWS($BU$29:BU46) -> 18 | BV46: {=INDEX('6. Unit Economics'!$B$61:$Y$61,1,$BU46)} -> 11.680603 | BW46: ='1. Assumptions'!$G$109 -> 12 | CB46: =ROWS($CB$29:CB46) -> 18 | CC46: {=INDEX('7. P&L + cash'!$D$37:$AA$37,1,$CB46)} -> 0.68247092 | CD46: ='1. Assumptions'!$G$92 -> 0.74
BF47: =ROWS($BF$29:BF47) -> 19 | BG47: {=(INDEX('7. P&L + cash'!$D$20:$AA$20,1,$BF47)+INDEX('3. Revenue Model'!$D$64:$AA$64,1,$BF47))*12} -> 122859.66 | BH47: {=INDEX('7. P&L + cash'!$D$21:$AA$21,1,$BF47)*12} -> 28465.075 | BI47: {=-INDEX('7. P&L + cash'!$D$23:$AA$23,1,$BF47)*12} -> -42917.555 | BJ47: {=-INDEX('7. P&L + cash'!$D$22:$AA$22,1,$BF47)*12} -> -13300.872 | BK47: {=INDEX('7. P&L + cash'!$D$24:$AA$24,1,$BF47)*12} -> 95106.305 | BN47: =ROWS($BN$29:BN47) -> 19 | BO47: {=INDEX('7. P&L + cash'!$D$84:$AA$84,1,$BN47)} -> 322737.38 | BP47: {=MAX(0,INDEX('7. P&L + cash'!$D$81:$AA$81,1,$BN47)*6)} -> 430741.29 | BU47: =ROWS($BU$29:BU47) -> 19 | BV47: {=INDEX('6. Unit Economics'!$B$61:$Y$61,1,$BU47)} -> 11.450576 | BW47: ='1. Assumptions'!$G$109 -> 12 | CB47: =ROWS($CB$29:CB47) -> 19 | CC47: {=INDEX('7. P&L + cash'!$D$37:$AA$37,1,$CB47)} -> 0.69301281 | CD47: ='1. Assumptions'!$G$92 -> 0.74
BF48: =ROWS($BF$29:BF48) -> 20 | BG48: {=(INDEX('7. P&L + cash'!$D$20:$AA$20,1,$BF48)+INDEX('3. Revenue Model'!$D$64:$AA$64,1,$BF48))*12} -> 133398 | BH48: {=INDEX('7. P&L + cash'!$D$21:$AA$21,1,$BF48)*12} -> 30692.018 | BI48: {=-INDEX('7. P&L + cash'!$D$23:$AA$23,1,$BF48)*12} -> -46088.153 | BJ48: {=-INDEX('7. P&L + cash'!$D$22:$AA$22,1,$BF48)*12} -> -14251.935 | BK48: {=INDEX('7. P&L + cash'!$D$24:$AA$24,1,$BF48)*12} -> 103749.93 | BN48: =ROWS($BN$29:BN48) -> 20 | BO48: {=INDEX('7. P&L + cash'!$D$84:$AA$84,1,$BN48)} -> 243174.39 | BP48: {=MAX(0,INDEX('7. P&L + cash'!$D$81:$AA$81,1,$BN48)*6)} -> 477377.93 | BU48: =ROWS($BU$29:BU48) -> 20 | BV48: {=INDEX('6. Unit Economics'!$B$61:$Y$61,1,$BU48)} -> 11.23943 | BW48: ='1. Assumptions'!$G$109 -> 12 | CB48: =ROWS($CB$29:CB48) -> 20 | CC48: {=INDEX('7. P&L + cash'!$D$37:$AA$37,1,$CB48)} -> 0.70294528 | CD48: ='1. Assumptions'!$G$92 -> 0.74
BF49: =ROWS($BF$29:BF49) -> 21 | BG49: {=(INDEX('7. P&L + cash'!$D$20:$AA$20,1,$BF49)+INDEX('3. Revenue Model'!$D$64:$AA$64,1,$BF49))*12} -> 144875.33 | BH49: {=INDEX('7. P&L + cash'!$D$21:$AA$21,1,$BF49)*12} -> 33141.131 | BI49: {=-INDEX('7. P&L + cash'!$D$23:$AA$23,1,$BF49)*12} -> -49555.353 | BJ49: {=-INDEX('7. P&L + cash'!$D$22:$AA$22,1,$BF49)*12} -> -15289.435 | BK49: {=INDEX('7. P&L + cash'!$D$24:$AA$24,1,$BF49)*12} -> 113171.67 | BN49: =ROWS($BN$29:BN49) -> 21 | BO49: {=INDEX('7. P&L + cash'!$D$84:$AA$84,1,$BN49)} -> 172837 | BP49: {=MAX(0,INDEX('7. P&L + cash'!$D$81:$AA$81,1,$BN49)*6)} -> 422024.32 | BU49: =ROWS($BU$29:BU49) -> 21 | BV49: {=INDEX('6. Unit Economics'!$B$61:$Y$61,1,$BU49)} -> 11.045204 | BW49: ='1. Assumptions'!$G$109 -> 12 | CB49: =ROWS($CB$29:CB49) -> 21 | CC49: {=INDEX('7. P&L + cash'!$D$37:$AA$37,1,$CB49)} -> 0.71228494 | CD49: ='1. Assumptions'!$G$92 -> 0.74
BF50: =ROWS($BF$29:BF50) -> 22 | BG50: {=(INDEX('7. P&L + cash'!$D$20:$AA$20,1,$BF50)+INDEX('3. Revenue Model'!$D$64:$AA$64,1,$BF50))*12} -> 157375.84 | BH50: {=INDEX('7. P&L + cash'!$D$21:$AA$21,1,$BF50)*12} -> 35833.06 | BI50: {=-INDEX('7. P&L + cash'!$D$23:$AA$23,1,$BF50)*12} -> -53346.306 | BJ50: {=-INDEX('7. P&L + cash'!$D$22:$AA$22,1,$BF50)*12} -> -16421.151 | BK50: {=INDEX('7. P&L + cash'!$D$24:$AA$24,1,$BF50)*12} -> 123441.45 | BN50: =ROWS($BN$29:BN50) -> 22 | BO50: {=INDEX('7. P&L + cash'!$D$84:$AA$84,1,$BN50)} -> 112636.26 | BP50: {=MAX(0,INDEX('7. P&L + cash'!$D$81:$AA$81,1,$BN50)*6)} -> 361204.45 | BU50: =ROWS($BU$29:BU50) -> 22 | BV50: {=INDEX('6. Unit Economics'!$B$61:$Y$61,1,$BU50)} -> 10.866137 | BW50: ='1. Assumptions'!$G$109 -> 12 | CB50: =ROWS($CB$29:CB50) -> 22 | CC50: {=INDEX('7. P&L + cash'!$D$37:$AA$37,1,$CB50)} -> 0.721051 | CD50: ='1. Assumptions'!$G$92 -> 0.74
BF51: =ROWS($BF$29:BF51) -> 23 | BG51: {=(INDEX('7. P&L + cash'!$D$20:$AA$20,1,$BF51)+INDEX('3. Revenue Model'!$D$64:$AA$64,1,$BF51))*12} -> 170991.87 | BH51: {=INDEX('7. P&L + cash'!$D$21:$AA$21,1,$BF51)*12} -> 38790.415 | BI51: {=-INDEX('7. P&L + cash'!$D$23:$AA$23,1,$BF51)*12} -> -57490.66 | BJ51: {=-INDEX('7. P&L + cash'!$D$22:$AA$22,1,$BF51)*12} -> -17655.566 | BK51: {=INDEX('7. P&L + cash'!$D$24:$AA$24,1,$BF51)*12} -> 134636.06 | BN51: =ROWS($BN$29:BN51) -> 23 | BO51: {=INDEX('7. P&L + cash'!$D$84:$AA$84,1,$BN51)} -> 5063570.2 | BP51: {=MAX(0,INDEX('7. P&L + cash'!$D$81:$AA$81,1,$BN51)*6)} -> 294396.62 | BU51: =ROWS($BU$29:BU51) -> 23 | BV51: {=INDEX('6. Unit Economics'!$B$61:$Y$61,1,$BU51)} -> 10.70065 | BW51: ='1. Assumptions'!$G$109 -> 12 | CB51: =ROWS($CB$29:CB51) -> 23 | CC51: {=INDEX('7. P&L + cash'!$D$37:$AA$37,1,$CB51)} -> 0.72926488 | CD51: ='1. Assumptions'!$G$92 -> 0.74
BF52: =ROWS($BF$29:BF52) -> 24 | BG52: {=(INDEX('7. P&L + cash'!$D$20:$AA$20,1,$BF52)+INDEX('3. Revenue Model'!$D$64:$AA$64,1,$BF52))*12} -> 185824.54 | BH52: {=INDEX('7. P&L + cash'!$D$21:$AA$21,1,$BF52)*12} -> 42037.973 | BI52: {=-INDEX('7. P&L + cash'!$D$23:$AA$23,1,$BF52)*12} -> -62020.818 | BJ52: {=-INDEX('7. P&L + cash'!$D$22:$AA$22,1,$BF52)*12} -> -19001.926 | BK52: {=INDEX('7. P&L + cash'!$D$24:$AA$24,1,$BF52)*12} -> 146839.77 | BN52: =ROWS($BN$29:BN52) -> 24 | BO52: {=INDEX('7. P&L + cash'!$D$84:$AA$84,1,$BN52)} -> 5026732 | BP52: {=MAX(0,INDEX('7. P&L + cash'!$D$81:$AA$81,1,$BN52)*6)} -> 221028.89 | BU52: =ROWS($BU$29:BU52) -> 24 | BV52: {=INDEX('6. Unit Economics'!$B$61:$Y$61,1,$BU52)} -> 10.547331 | BW52: ='1. Assumptions'!$G$109 -> 12 | CB52: =ROWS($CB$29:CB52) -> 24 | CC52: {=INDEX('7. P&L + cash'!$D$37:$AA$37,1,$CB52)} -> 0.73694968 | CD52: ='1. Assumptions'!$G$92 -> 0.74

Sheet 3. Revenue Model
A1: LaunchPlan AI: Revenue Model | F1: YELLOW = Hardcoded Input | G1: BLUE = Formula | H1: GREEN = Dashboard Output | I1: RED = Check / Warning
A2: Section | B2: Line Item | C2: Unit | D2: Month 1 | E2: Month 2 | F2: Month 3 | G2: Month 4 | H2: Month 5 | I2: Month 6 | J2: Month 7 | K2: Month 8 | L2: Month 9 | M2: Month 10 | N2: Month 11 | O2: Month 12 | P2: Month 13 | Q2: Month 14 | R2: Month 15 | S2: Month 16 | T2: Month 17 | U2: Month 18 | V2: Month 19 | W2: Month 20 | X2: Month 21 | Y2: Month 22 | Z2: Month 23 | AA2: Month 24 | AB2: Notes / Formula Logic | AC2: Check / Source
A3: § 1 CONTROL & TIMELINE
A4: Control | B4: Selected Scenario | C4: Text | D4: =INDEX('1. Assumptions'!$G:$G,MATCH("Selected Scenario",'1. Assumptions'!$B:$B,0)) -> Base | E4: =INDEX('1. Assumptions'!$G:$G,MATCH("Selected Scenario",'1. Assumptions'!$B:$B,0)) -> Base | F4: =INDEX('1. Assumptions'!$G:$G,MATCH("Selected Scenario",'1. Assumptions'!$B:$B,0)) -> Base | G4: =INDEX('1. Assumptions'!$G:$G,MATCH("Selected Scenario",'1. Assumptions'!$B:$B,0)) -> Base | H4: =INDEX('1. Assumptions'!$G:$G,MATCH("Selected Scenario",'1. Assumptions'!$B:$B,0)) -> Base | I4: =INDEX('1. Assumptions'!$G:$G,MATCH("Selected Scenario",'1. Assumptions'!$B:$B,0)) -> Base | J4: =INDEX('1. Assumptions'!$G:$G,MATCH("Selected Scenario",'1. Assumptions'!$B:$B,0)) -> Base | K4: =INDEX('1. Assumptions'!$G:$G,MATCH("Selected Scenario",'1. Assumptions'!$B:$B,0)) -> Base | ... AA4: =INDEX('1. Assumptions'!$G:$G,MATCH("Selected Scenario",'1. Assumptions'!$B:$B,0)) -> Base | AC4: Links from Assumptions tab Control Panel
A5: Timeline | B5: Month Number | C5: Month | D5: 1 | E5: =D5+1 -> 2 | F5: =E5+1 -> 3 | G5: =F5+1 -> 4 | H5: =G5+1 -> 5 | I5: =H5+1 -> 6 | J5: =I5+1 -> 7 | K5: =J5+1 -> 8 | L5: =K5+1 -> 9 | ... AA5: =Z5+1 -> 24
A6: Timeline | B6: Calendar Month | C6: Date | D6: =EDATE(INDEX('1. Assumptions'!$G:$G,MATCH("Start Date",'1. Assumptions'!$B:$B,0)),D5-1) -> 46023 | E6: =EDATE(INDEX('1. Assumptions'!$G:$G,MATCH("Start Date",'1. Assumptions'!$B:$B,0)),E5-1) -> 46054 | F6: =EDATE(INDEX('1. Assumptions'!$G:$G,MATCH("Start Date",'1. Assumptions'!$B:$B,0)),F5-1) -> 46082 | G6: =EDATE(INDEX('1. Assumptions'!$G:$G,MATCH("Start Date",'1. Assumptions'!$B:$B,0)),G5-1) -> 46113 | H6: =EDATE(INDEX('1. Assumptions'!$G:$G,MATCH("Start Date",'1. Assumptions'!$B:$B,0)),H5-1) -> 46143 | I6: =EDATE(INDEX('1. Assumptions'!$G:$G,MATCH("Start Date",'1. Assumptions'!$B:$B,0)),I5-1) -> 46174 | J6: =EDATE(INDEX('1. Assumptions'!$G:$G,MATCH("Start Date",'1. Assumptions'!$B:$B,0)),J5-1) -> 46204 | K6: =EDATE(INDEX('1. Assumptions'!$G:$G,MATCH("Start Date",'1. Assumptions'!$B:$B,0)),K5-1) -> 46235 | ... AA6: =EDATE(INDEX('1. Assumptions'!$G:$G,MATCH("Start Date",'1. Assumptions'!$B:$B,0)),AA5-1) -> 46722 | AC6: EDATE(Start_Date, MonthNum-1) — links to Assumptions Start Date
A8: § 2 FREE USER FUNNEL
A9: Free Funnel | B9: Beginning Active Free Users | C9: Users | D9: =INDEX('1. Assumptions'!$G:$G,MATCH("Starting Free Users",'1. Assumptions'!$B:$B,0))*INDEX('1. Assumptions'!$G:$G,MATCH("Free User Activation Rate",'1. Assumptions'!B:B,0)) -> 800 | E9: =D14 -> 784 | F9: =E14 -> 787.52 | G9: =F14 -> 807.8656 | H9: =G14 -> 843.09517 | I9: =H14 -> 891.87023 | J9: =I14 -> 953.34038 | K9: =J14 -> 1027.0553 | L9: =K14 -> 1112.8978 | ... AA9: =Z14 -> 4478.1404 | AC9: M1: Starting Free Users × Activation Rate; M2+: Prior Ending Active Free Users
A10: Free Funnel | B10: New Free Users | C10: Users | D10: =INDEX('1. Assumptions'!$G:$G,MATCH("New Free Users ; M1",'1. Assumptions'!$B:$B,0)) -> 400 | E10: =D10*(1+INDEX('1. Assumptions'!$G:$G,MATCH("Free User Monthly Growth Rate (MoM)",'1. Assumptions'!$B:$B,0))) -> 440 | F10: =E10*(1+INDEX('1. Assumptions'!$G:$G,MATCH("Free User Monthly Growth Rate (MoM)",'1. Assumptions'!$B:$B,0))) -> 484 | G10: =F10*(1+INDEX('1. Assumptions'!$G:$G,MATCH("Free User Monthly Growth Rate (MoM)",'1. Assumptions'!$B:$B,0))) -> 532.4 | H10: =G10*(1+INDEX('1. Assumptions'!$G:$G,MATCH("Free User Monthly Growth Rate (MoM)",'1. Assumptions'!$B:$B,0))) -> 585.64 | I10: =H10*(1+INDEX('1. Assumptions'!$G:$G,MATCH("Free User Monthly Growth Rate (MoM)",'1. Assumptions'!$B:$B,0))) -> 644.204 | J10: =I10*(1+INDEX('1. Assumptions'!$G:$G,MATCH("Free User Monthly Growth Rate (MoM)",'1. Assumptions'!$B:$B,0))) -> 708.6244 | K10: =J10*(1+INDEX('1. Assumptions'!$G:$G,MATCH("Free User Monthly Growth Rate (MoM)",'1. Assumptions'!$B:$B,0))) -> 779.48684 | L10: =K10*(1+INDEX('1. Assumptions'!$G:$G,MATCH("Free User Monthly Growth Rate (MoM)",'1. Assumptions'!$B:$B,0))) -> 857.43552 | ... AA10: =Z10*(1+INDEX('1. Assumptions'!$G:$G,MATCH("Free User Monthly Growth Rate (MoM)",'1. Assumptions'!$B:$B,0))) -> 3581.721 | AC10: XLOOKUP "New Free Users M1" × (1+Growth Rate) each month
A11: Free Funnel | B11: New Activated Free Users | C11: Users | D11: =D10*INDEX('1. Assumptions'!$G:$G,MATCH("Free User Activation Rate",'1. Assumptions'!$B:$B,0)) -> 160 | E11: =E10*INDEX('1. Assumptions'!$G:$G,MATCH("Free User Activation Rate",'1. Assumptions'!$B:$B,0)) -> 176 | F11: =F10*INDEX('1. Assumptions'!$G:$G,MATCH("Free User Activation Rate",'1. Assumptions'!$B:$B,0)) -> 193.6 | G11: =G10*INDEX('1. Assumptions'!$G:$G,MATCH("Free User Activation Rate",'1. Assumptions'!$B:$B,0)) -> 212.96 | H11: =H10*INDEX('1. Assumptions'!$G:$G,MATCH("Free User Activation Rate",'1. Assumptions'!$B:$B,0)) -> 234.256 | I11: =I10*INDEX('1. Assumptions'!$G:$G,MATCH("Free User Activation Rate",'1. Assumptions'!$B:$B,0)) -> 257.6816 | J11: =J10*INDEX('1. Assumptions'!$G:$G,MATCH("Free User Activation Rate",'1. Assumptions'!$B:$B,0)) -> 283.44976 | K11: =K10*INDEX('1. Assumptions'!$G:$G,MATCH("Free User Activation Rate",'1. Assumptions'!$B:$B,0)) -> 311.79474 | ... AA11: =AA10*INDEX('1. Assumptions'!$G:$G,MATCH("Free User Activation Rate",'1. Assumptions'!$B:$B,0)) -> 1432.6884
A12: Free Funnel | B12: Free-to-Starter Conversions | C12: Customers | D12: =D9*INDEX('1. Assumptions'!$G:$G,MATCH("Free-to-Starter Conversion",'1. Assumptions'!$B:$B,0)) -> 32 | E12: =E9*INDEX('1. Assumptions'!$G:$G,MATCH("Free-to-Starter Conversion",'1. Assumptions'!$B:$B,0)) -> 31.36 | F12: =F9*INDEX('1. Assumptions'!$G:$G,MATCH("Free-to-Starter Conversion",'1. Assumptions'!$B:$B,0)) -> 31.5008 | G12: =G9*INDEX('1. Assumptions'!$G:$G,MATCH("Free-to-Starter Conversion",'1. Assumptions'!$B:$B,0)) -> 32.314624 | H12: =H9*INDEX('1. Assumptions'!$G:$G,MATCH("Free-to-Starter Conversion",'1. Assumptions'!$B:$B,0)) -> 33.723807 | I12: =I9*INDEX('1. Assumptions'!$G:$G,MATCH("Free-to-Starter Conversion",'1. Assumptions'!$B:$B,0)) -> 35.674809 | J12: =J9*INDEX('1. Assumptions'!$G:$G,MATCH("Free-to-Starter Conversion",'1. Assumptions'!$B:$B,0)) -> 38.133615 | K12: =K9*INDEX('1. Assumptions'!$G:$G,MATCH("Free-to-Starter Conversion",'1. Assumptions'!$B:$B,0)) -> 41.08221 | ... AA12: =AA9*INDEX('1. Assumptions'!$G:$G,MATCH("Free-to-Starter Conversion",'1. Assumptions'!$B:$B,0)) -> 179.12562 | AC12: Only ACTIVE free users convert to paid — not total free users
A13: Free Funnel | B13: Dormant Free Users | C13: Users | D13: =D9*INDEX('1. Assumptions'!$G:$G,MATCH("Free User Decay Rate (dormancy)",'1. Assumptions'!$B:$B,0)) -> 144 | E13: =E9*INDEX('1. Assumptions'!$G:$G,MATCH("Free User Decay Rate (dormancy)",'1. Assumptions'!$B:$B,0)) -> 141.12 | F13: =F9*INDEX('1. Assumptions'!$G:$G,MATCH("Free User Decay Rate (dormancy)",'1. Assumptions'!$B:$B,0)) -> 141.7536 | G13: =G9*INDEX('1. Assumptions'!$G:$G,MATCH("Free User Decay Rate (dormancy)",'1. Assumptions'!$B:$B,0)) -> 145.41581 | H13: =H9*INDEX('1. Assumptions'!$G:$G,MATCH("Free User Decay Rate (dormancy)",'1. Assumptions'!$B:$B,0)) -> 151.75713 | I13: =I9*INDEX('1. Assumptions'!$G:$G,MATCH("Free User Decay Rate (dormancy)",'1. Assumptions'!$B:$B,0)) -> 160.53664 | J13: =J9*INDEX('1. Assumptions'!$G:$G,MATCH("Free User Decay Rate (dormancy)",'1. Assumptions'!$B:$B,0)) -> 171.60127 | K13: =K9*INDEX('1. Assumptions'!$G:$G,MATCH("Free User Decay Rate (dormancy)",'1. Assumptions'!$B:$B,0)) -> 184.86995 | ... AA13: =AA9*INDEX('1. Assumptions'!$G:$G,MATCH("Free User Decay Rate (dormancy)",'1. Assumptions'!$B:$B,0)) -> 806.06528
A14: Free Funnel | B14: Ending Active Free Users | C14: Users | D14: =D9+D11-D12-D13 -> 784 | E14: =E9+E11-E12-E13 -> 787.52 | F14: =F9+F11-F12-F13 -> 807.8656 | G14: =G9+G11-G12-G13 -> 843.09517 | H14: =H9+H11-H12-H13 -> 891.87023 | I14: =I9+I11-I12-I13 -> 953.34038 | J14: =J9+J11-J12-J13 -> 1027.0553 | K14: =K9+K11-K12-K13 -> 1112.8978 | ... AA14: =AA9+AA11-AA12-AA13 -> 4925.6379 | AC14: Beginning + New Activated - Free-to-Starter Conversions - Dormant
A16: § 3 NEW LOGO ACQUISITION
A17: Acquisition | B17: New Starter Logos – Direct/Self-Serve | C17: Customers | D17: =INDEX('1. Assumptions'!$G:$G,MATCH("New Starter Logos ; M1",'1. Assumptions'!$B:$B,0)) -> 8 | E17: =D17*(1+INDEX('1. Assumptions'!$G:$G,MATCH("Monthly New Logo Growth Rate (MoM)",'1. Assumptions'!$B:$B,0))) -> 8.56 | F17: =E17*(1+INDEX('1. Assumptions'!$G:$G,MATCH("Monthly New Logo Growth Rate (MoM)",'1. Assumptions'!$B:$B,0))) -> 9.1592 | G17: =F17*(1+INDEX('1. Assumptions'!$G:$G,MATCH("Monthly New Logo Growth Rate (MoM)",'1. Assumptions'!$B:$B,0))) -> 9.800344 | H17: =G17*(1+INDEX('1. Assumptions'!$G:$G,MATCH("Monthly New Logo Growth Rate (MoM)",'1. Assumptions'!$B:$B,0))) -> 10.486368 | I17: =H17*(1+INDEX('1. Assumptions'!$G:$G,MATCH("Monthly New Logo Growth Rate (MoM)",'1. Assumptions'!$B:$B,0))) -> 11.220414 | J17: =I17*(1+INDEX('1. Assumptions'!$G:$G,MATCH("Monthly New Logo Growth Rate (MoM)",'1. Assumptions'!$B:$B,0))) -> 12.005843 | K17: =J17*(1+INDEX('1. Assumptions'!$G:$G,MATCH("Monthly New Logo Growth Rate (MoM)",'1. Assumptions'!$B:$B,0))) -> 12.846252 | L17: =K17*(1+INDEX('1. Assumptions'!$G:$G,MATCH("Monthly New Logo Growth Rate (MoM)",'1. Assumptions'!$B:$B,0))) -> 13.745489 | ... AA17: =Z17*(1+INDEX('1. Assumptions'!$G:$G,MATCH("Monthly New Logo Growth Rate (MoM)",'1. Assumptions'!$B:$B,0))) -> 37.924239
A18: Acquisition | B18: New Growth Logos – Direct | C18: Customers | D18: =INDEX('1. Assumptions'!$G:$G,MATCH("New Growth Logos ; M1",'1. Assumptions'!$B:$B,0)) -> 4 | E18: =D18*(1+INDEX('1. Assumptions'!$G:$G,MATCH("Monthly New Logo Growth Rate (MoM)",'1. Assumptions'!$B:$B,0))) -> 4.28 | F18: =E18*(1+INDEX('1. Assumptions'!$G:$G,MATCH("Monthly New Logo Growth Rate (MoM)",'1. Assumptions'!$B:$B,0))) -> 4.5796 | G18: =F18*(1+INDEX('1. Assumptions'!$G:$G,MATCH("Monthly New Logo Growth Rate (MoM)",'1. Assumptions'!$B:$B,0))) -> 4.900172 | H18: =G18*(1+INDEX('1. Assumptions'!$G:$G,MATCH("Monthly New Logo Growth Rate (MoM)",'1. Assumptions'!$B:$B,0))) -> 5.243184 | I18: =H18*(1+INDEX('1. Assumptions'!$G:$G,MATCH("Monthly New Logo Growth Rate (MoM)",'1. Assumptions'!$B:$B,0))) -> 5.6102069 | J18: =I18*(1+INDEX('1. Assumptions'!$G:$G,MATCH("Monthly New Logo Growth Rate (MoM)",'1. Assumptions'!$B:$B,0))) -> 6.0029214 | K18: =J18*(1+INDEX('1. Assumptions'!$G:$G,MATCH("Monthly New Logo Growth Rate (MoM)",'1. Assumptions'!$B:$B,0))) -> 6.4231259 | L18: =K18*(1+INDEX('1. Assumptions'!$G:$G,MATCH("Monthly New Logo Growth Rate (MoM)",'1. Assumptions'!$B:$B,0))) -> 6.8727447 | ... AA18: =Z18*(1+INDEX('1. Assumptions'!$G:$G,MATCH("Monthly New Logo Growth Rate (MoM)",'1. Assumptions'!$B:$B,0))) -> 18.962119
A19: Acquisition | B19: New Enterprise Logos | C19: Customers | D19: =IF(1<INDEX('1. Assumptions'!$G:$G,MATCH("Enterprise Motion Start Month",'1. Assumptions'!$B:$B,0)),0,INDEX('1. Assumptions'!$G:$G,MATCH("New Enterprise Logos ; M6+",'1. Assumptions'!$B:$B,0))) -> 0 | E19: =IF(E5<INDEX('1. Assumptions'!$G:$G,MATCH("Enterprise Motion Start Month",'1. Assumptions'!$B:$B,0)),0,INDEX('1. Assumptions'!$G:$G,MATCH("New Enterprise Logos ; M6+",'1. Assumptions'!$B:$B,0))*(1+INDEX('1. Assumptions'!$G:$G,MATCH("Monthly New Logo Growth Rate (MoM)",'1. Assumptions'!$B:$B,0)))^(E5-INDEX('1. Assumptions'!$G:$G,MATCH("Enterprise Motion Start Month",'1. Assumptions'!$B:$B,0)))) -> 0 | F19: =IF(F5<INDEX('1. Assumptions'!$G:$G,MATCH("Enterprise Motion Start Month",'1. Assumptions'!$B:$B,0)),0,INDEX('1. Assumptions'!$G:$G,MATCH("New Enterprise Logos ; M6+",'1. Assumptions'!$B:$B,0))*(1+INDEX('1. Assumptions'!$G:$G,MATCH("Monthly New Logo Growth Rate (MoM)",'1. Assumptions'!$B:$B,0)))^(F5-INDEX('1. Assumptions'!$G:$G,MATCH("Enterprise Motion Start Month",'1. Assumptions'!$B:$B,0)))) -> 0 | G19: =IF(G5<INDEX('1. Assumptions'!$G:$G,MATCH("Enterprise Motion Start Month",'1. Assumptions'!$B:$B,0)),0,INDEX('1. Assumptions'!$G:$G,MATCH("New Enterprise Logos ; M6+",'1. Assumptions'!$B:$B,0))*(1+INDEX('1. Assumptions'!$G:$G,MATCH("Monthly New Logo Growth Rate (MoM)",'1. Assumptions'!$B:$B,0)))^(G5-INDEX('1. Assumptions'!$G:$G,MATCH("Enterprise Motion Start Month",'1. Assumptions'!$B:$B,0)))) -> 0 | H19: =IF(H5<INDEX('1. Assumptions'!$G:$G,MATCH("Enterprise Motion Start Month",'1. Assumptions'!$B:$B,0)),0,INDEX('1. Assumptions'!$G:$G,MATCH("New Enterprise Logos ; M6+",'1. Assumptions'!$B:$B,0))*(1+INDEX('1. Assumptions'!$G:$G,MATCH("Monthly New Logo Growth Rate (MoM)",'1. Assumptions'!$B:$B,0)))^(H5-INDEX('1. Assumptions'!$G:$G,MATCH("Enterprise Motion Start Month",'1. Assumptions'!$B:$B,0)))) -> 0 | I19: =IF(I5<INDEX('1. Assumptions'!$G:$G,MATCH("Enterprise Motion Start Month",'1. Assumptions'!$B:$B,0)),0,INDEX('1. Assumptions'!$G:$G,MATCH("New Enterprise Logos ; M6+",'1. Assumptions'!$B:$B,0))*(1+INDEX('1. Assumptions'!$G:$G,MATCH("Monthly New Logo Growth Rate (MoM)",'1. Assumptions'!$B:$B,0)))^(I5-INDEX('1. Assumptions'!$G:$G,MATCH("Enterprise Motion Start Month",'1. Assumptions'!$B:$B,0)))) -> 1 | J19: =IF(J5<INDEX('1. Assumptions'!$G:$G,MATCH("Enterprise Motion Start Month",'1. Assumptions'!$B:$B,0)),0,INDEX('1. Assumptions'!$G:$G,MATCH("New Enterprise Logos ; M6+",'1. Assumptions'!$B:$B,0))*(1+INDEX('1. Assumptions'!$G:$G,MATCH("Monthly New Logo Growth Rate (MoM)",'1. Assumptions'!$B:$B,0)))^(J5-INDEX('1. Assumptions'!$G:$G,MATCH("Enterprise Motion Start Month",'1. Assumptions'!$B:$B,0)))) -> 1.07 | K19: =IF(K5<INDEX('1. Assumptions'!$G:$G,MATCH("Enterprise Motion Start Month",'1. Assumptions'!$B:$B,0)),0,INDEX('1. Assumptions'!$G:$G,MATCH("New Enterprise Logos ; M6+",'1. Assumptions'!$B:$B,0))*(1+INDEX('1. Assumptions'!$G:$G,MATCH("Monthly New Logo Growth Rate (MoM)",'1. Assumptions'!$B:$B,0)))^(K5-INDEX('1. Assumptions'!$G:$G,MATCH("Enterprise Motion Start Month",'1. Assumptions'!$B:$B,0)))) -> 1.1449 | L19: =IF(L5<INDEX('1. Assumptions'!$G:$G,MATCH("Enterprise Motion Start Month",'1. Assumptions'!$B:$B,0)),0,INDEX('1. Assumptions'!$G:$G,MATCH("New Enterprise Logos ; M6+",'1. Assumptions'!$B:$B,0))*(1+INDEX('1. Assumptions'!$G:$G,MATCH("Monthly New Logo Growth Rate (MoM)",'1. Assumptions'!$B:$B,0)))^(L5-INDEX('1. Assumptions'!$G:$G,MATCH("Enterprise Motion Start Month",'1. Assumptions'!$B:$B,0)))) -> 1.225043 | ... AA19: =IF(AA5<INDEX('1. Assumptions'!$G:$G,MATCH("Enterprise Motion Start Month",'1. Assumptions'!$B:$B,0)),0,INDEX('1. Assumptions'!$G:$G,MATCH("New Enterprise Logos ; M6+",'1. Assumptions'!$B:$B,0))*(1+INDEX('1. Assumptions'!$G:$G,MATCH("Monthly New Logo Growth Rate (MoM)",'1. Assumptions'!$B:$B,0)))^(AA5-INDEX('1. Assumptions'!$G:$G,MATCH("Enterprise Motion Start Month",'1. Assumptions'!$B:$B,0)))) -> 3.3799323 | AC19: 0 before Enterprise Motion Start Month; grows monthly after
A20: Acquisition | B20: Free-to-Starter Conversions (from Free Funnel) | C20: Customers | D20: =D12 -> 32 | E20: =E12 -> 31.36 | F20: =F12 -> 31.5008 | G20: =G12 -> 32.314624 | H20: =H12 -> 33.723807 | I20: =I12 -> 35.674809 | J20: =J12 -> 38.133615 | K20: =K12 -> 41.08221 | ... AA20: =AA12 -> 179.12562
A21: Acquisition | B21: Total New Paid Logos | C21: Customers | D21: =D17+D18+D19+D20 -> 44 | E21: =E17+E18+E19+E20 -> 44.2 | F21: =F17+F18+F19+F20 -> 45.2396 | G21: =G17+G18+G19+G20 -> 47.01514 | H21: =H17+H18+H19+H20 -> 49.453359 | I21: =I17+I18+I19+I20 -> 53.50543 | J21: =J17+J18+J19+J20 -> 57.212379 | K21: =K17+K18+K19+K20 -> 61.496488 | ... AA21: =AA17+AA18+AA19+AA20 -> 239.39191 | AC21: Starter + Growth + Enterprise + Free-to-Starter
A23: § 4 STARTER CUSTOMER ROLL-FORWARD
A24: Starter Customers | B24: Beginning Starter Customers | C24: Customers | D24: =INDEX('1. Assumptions'!$G:$G,MATCH("Starting Starter Customers",'1. Assumptions'!$B:$B,0)) -> 300 | E24: =D29 -> 334 | F24: =E29 -> 353.88 | G24: =F29 -> 373.3072 | H24: =G29 -> 393.02374 | I24: =H29 -> 413.65249 | J24: =I29 -> 435.72856 | K24: =J29 -> 459.7243 | L24: =K29 -> 486.06931 | ... AA24: =Z29 -> 1459.2527
A25: Starter Customers | B25: New Starter Logos | C25: Customers | D25: =D17 -> 8 | E25: =E17 -> 8.56 | F25: =F17 -> 9.1592 | G25: =G17 -> 9.800344 | H25: =H17 -> 10.486368 | I25: =I17 -> 11.220414 | J25: =J17 -> 12.005843 | K25: =K17 -> 12.846252 | ... AA25: =AA17 -> 37.924239
A26: Starter Customers | B26: Free-to-Starter Conversions | C26: Customers | D26: =D12 -> 32 | E26: =E12 -> 31.36 | F26: =F12 -> 31.5008 | G26: =G12 -> 32.314624 | H26: =H12 -> 33.723807 | I26: =I12 -> 35.674809 | J26: =J12 -> 38.133615 | K26: =K12 -> 41.08221 | ... AA26: =AA12 -> 179.12562
A27: Starter Customers | B27: Starter-to-Growth Upgrades | C27: Customers | D27: =D24*INDEX('1. Assumptions'!$G:$G,MATCH("Starter-to-Growth Monthly Upgrade Rate",'1. Assumptions'!$B:$B,0)) -> 6 | E27: =E24*INDEX('1. Assumptions'!$G:$G,MATCH("Starter-to-Growth Monthly Upgrade Rate",'1. Assumptions'!$B:$B,0)) -> 6.68 | F27: =F24*INDEX('1. Assumptions'!$G:$G,MATCH("Starter-to-Growth Monthly Upgrade Rate",'1. Assumptions'!$B:$B,0)) -> 7.0776 | G27: =G24*INDEX('1. Assumptions'!$G:$G,MATCH("Starter-to-Growth Monthly Upgrade Rate",'1. Assumptions'!$B:$B,0)) -> 7.466144 | H27: =H24*INDEX('1. Assumptions'!$G:$G,MATCH("Starter-to-Growth Monthly Upgrade Rate",'1. Assumptions'!$B:$B,0)) -> 7.8604747 | I27: =I24*INDEX('1. Assumptions'!$G:$G,MATCH("Starter-to-Growth Monthly Upgrade Rate",'1. Assumptions'!$B:$B,0)) -> 8.2730497 | J27: =J24*INDEX('1. Assumptions'!$G:$G,MATCH("Starter-to-Growth Monthly Upgrade Rate",'1. Assumptions'!$B:$B,0)) -> 8.7145712 | K27: =K24*INDEX('1. Assumptions'!$G:$G,MATCH("Starter-to-Growth Monthly Upgrade Rate",'1. Assumptions'!$B:$B,0)) -> 9.1944861 | ... AA27: =AA24*INDEX('1. Assumptions'!$G:$G,MATCH("Starter-to-Growth Monthly Upgrade Rate",'1. Assumptions'!$B:$B,0)) -> 29.185054
A28: Starter Customers | B28: Starter Churned Customers | C28: Customers | D28: =IF(D5<INDEX('1. Assumptions'!$G:$G,MATCH("Churn Start Month",'1. Assumptions'!$B:$B,0)),0,D24*INDEX('1. Assumptions'!$G:$G,MATCH("Starter Monthly Churn",'1. Assumptions'!$B:$B,0))) -> 0 | E28: =IF(E5<INDEX('1. Assumptions'!$G:$G,MATCH("Churn Start Month",'1. Assumptions'!$B:$B,0)),0,E24*INDEX('1. Assumptions'!$G:$G,MATCH("Starter Monthly Churn",'1. Assumptions'!$B:$B,0))) -> 13.36 | F28: =IF(F5<INDEX('1. Assumptions'!$G:$G,MATCH("Churn Start Month",'1. Assumptions'!$B:$B,0)),0,F24*INDEX('1. Assumptions'!$G:$G,MATCH("Starter Monthly Churn",'1. Assumptions'!$B:$B,0))) -> 14.1552 | G28: =IF(G5<INDEX('1. Assumptions'!$G:$G,MATCH("Churn Start Month",'1. Assumptions'!$B:$B,0)),0,G24*INDEX('1. Assumptions'!$G:$G,MATCH("Starter Monthly Churn",'1. Assumptions'!$B:$B,0))) -> 14.932288 | H28: =IF(H5<INDEX('1. Assumptions'!$G:$G,MATCH("Churn Start Month",'1. Assumptions'!$B:$B,0)),0,H24*INDEX('1. Assumptions'!$G:$G,MATCH("Starter Monthly Churn",'1. Assumptions'!$B:$B,0))) -> 15.720949 | I28: =IF(I5<INDEX('1. Assumptions'!$G:$G,MATCH("Churn Start Month",'1. Assumptions'!$B:$B,0)),0,I24*INDEX('1. Assumptions'!$G:$G,MATCH("Starter Monthly Churn",'1. Assumptions'!$B:$B,0))) -> 16.546099 | J28: =IF(J5<INDEX('1. Assumptions'!$G:$G,MATCH("Churn Start Month",'1. Assumptions'!$B:$B,0)),0,J24*INDEX('1. Assumptions'!$G:$G,MATCH("Starter Monthly Churn",'1. Assumptions'!$B:$B,0))) -> 17.429142 | K28: =IF(K5<INDEX('1. Assumptions'!$G:$G,MATCH("Churn Start Month",'1. Assumptions'!$B:$B,0)),0,K24*INDEX('1. Assumptions'!$G:$G,MATCH("Starter Monthly Churn",'1. Assumptions'!$B:$B,0))) -> 18.388972 | ... AA28: =IF(AA5<INDEX('1. Assumptions'!$G:$G,MATCH("Churn Start Month",'1. Assumptions'!$B:$B,0)),0,AA24*INDEX('1. Assumptions'!$G:$G,MATCH("Starter Monthly Churn",'1. Assumptions'!$B:$B,0))) -> 58.370108
A29: Starter Customers | B29: Ending Starter Customers | C29: Customers | D29: =D24+D25+D26-D27-D28 -> 334 | E29: =E24+E25+E26-E27-E28 -> 353.88 | F29: =F24+F25+F26-F27-F28 -> 373.3072 | G29: =G24+G25+G26-G27-G28 -> 393.02374 | H29: =H24+H25+H26-H27-H28 -> 413.65249 | I29: =I24+I25+I26-I27-I28 -> 435.72856 | J29: =J24+J25+J26-J27-J28 -> 459.7243 | K29: =K24+K25+K26-K27-K28 -> 486.06931 | ... AA29: =AA24+AA25+AA26-AA27-AA28 -> 1588.7474 | AC29: Beginning + New + Free Conversions - Upgrades - Churn
A31: § 5 GROWTH CUSTOMER ROLL-FORWARD
A32: Growth Customers | B32: Beginning Growth Customers | C32: Customers | D32: =INDEX('1. Assumptions'!$G:$G,MATCH("Starting Growth Customers",'1. Assumptions'!$B:$B,0)) -> 180 | E32: =D37 -> 189.55 | F32: =E37 -> 195.29738 | G32: =F37 -> 201.5839 | H32: =G37 -> 208.40666 | I32: =H37 -> 215.77913 | J32: =I37 -> 223.72846 | K32: =J37 -> 232.29342 | L32: =K37 -> 241.52297 | ... AA32: =Z37 -> 519.6969
A33: Growth Customers | B33: New Growth Logos | C33: Customers | D33: =D18 -> 4 | E33: =E18 -> 4.28 | F33: =F18 -> 4.5796 | G33: =G18 -> 4.900172 | H33: =H18 -> 5.243184 | I33: =I18 -> 5.6102069 | J33: =J18 -> 6.0029214 | K33: =K18 -> 6.4231259 | ... AA33: =AA18 -> 18.962119
A34: Growth Customers | B34: Upgrades from Starter | C34: Customers | D34: =D27 -> 6 | E34: =E27 -> 6.68 | F34: =F27 -> 7.0776 | G34: =G27 -> 7.466144 | H34: =H27 -> 7.8604747 | I34: =I27 -> 8.2730497 | J34: =J27 -> 8.7145712 | K34: =K27 -> 9.1944861 | ... AA34: =AA27 -> 29.185054
A35: Growth Customers | B35: Growth-to-Enterprise Upgrades | C35: Customers | D35: =D32*INDEX('1. Assumptions'!$G:$G,MATCH("Growth-to-Enterprise Monthly Upgrade Rate",'1. Assumptions'!$B:$B,0)) -> 0.45 | E35: =E32*INDEX('1. Assumptions'!$G:$G,MATCH("Growth-to-Enterprise Monthly Upgrade Rate",'1. Assumptions'!$B:$B,0)) -> 0.473875 | F35: =F32*INDEX('1. Assumptions'!$G:$G,MATCH("Growth-to-Enterprise Monthly Upgrade Rate",'1. Assumptions'!$B:$B,0)) -> 0.48824344 | G35: =G32*INDEX('1. Assumptions'!$G:$G,MATCH("Growth-to-Enterprise Monthly Upgrade Rate",'1. Assumptions'!$B:$B,0)) -> 0.50395974 | H35: =H32*INDEX('1. Assumptions'!$G:$G,MATCH("Growth-to-Enterprise Monthly Upgrade Rate",'1. Assumptions'!$B:$B,0)) -> 0.52101664 | I35: =I32*INDEX('1. Assumptions'!$G:$G,MATCH("Growth-to-Enterprise Monthly Upgrade Rate",'1. Assumptions'!$B:$B,0)) -> 0.53944783 | J35: =J32*INDEX('1. Assumptions'!$G:$G,MATCH("Growth-to-Enterprise Monthly Upgrade Rate",'1. Assumptions'!$B:$B,0)) -> 0.55932116 | K35: =K32*INDEX('1. Assumptions'!$G:$G,MATCH("Growth-to-Enterprise Monthly Upgrade Rate",'1. Assumptions'!$B:$B,0)) -> 0.58073356 | ... AA35: =AA32*INDEX('1. Assumptions'!$G:$G,MATCH("Growth-to-Enterprise Monthly Upgrade Rate",'1. Assumptions'!$B:$B,0)) -> 1.2992423
A36: Growth Customers | B36: Growth Churned Customers | C36: Customers | D36: =IF(D5<INDEX('1. Assumptions'!$G:$G,MATCH("Churn Start Month",'1. Assumptions'!$B:$B,0)),0,D32*INDEX('1. Assumptions'!$G:$G,MATCH("Growth Monthly Churn",'1. Assumptions'!$B:$B,0))) -> 0 | E36: =IF(E5<INDEX('1. Assumptions'!$G:$G,MATCH("Churn Start Month",'1. Assumptions'!$B:$B,0)),0,E32*INDEX('1. Assumptions'!$G:$G,MATCH("Growth Monthly Churn",'1. Assumptions'!$B:$B,0))) -> 4.73875 | F36: =IF(F5<INDEX('1. Assumptions'!$G:$G,MATCH("Churn Start Month",'1. Assumptions'!$B:$B,0)),0,F32*INDEX('1. Assumptions'!$G:$G,MATCH("Growth Monthly Churn",'1. Assumptions'!$B:$B,0))) -> 4.8824344 | G36: =IF(G5<INDEX('1. Assumptions'!$G:$G,MATCH("Churn Start Month",'1. Assumptions'!$B:$B,0)),0,G32*INDEX('1. Assumptions'!$G:$G,MATCH("Growth Monthly Churn",'1. Assumptions'!$B:$B,0))) -> 5.0395974 | H36: =IF(H5<INDEX('1. Assumptions'!$G:$G,MATCH("Churn Start Month",'1. Assumptions'!$B:$B,0)),0,H32*INDEX('1. Assumptions'!$G:$G,MATCH("Growth Monthly Churn",'1. Assumptions'!$B:$B,0))) -> 5.2101664 | I36: =IF(I5<INDEX('1. Assumptions'!$G:$G,MATCH("Churn Start Month",'1. Assumptions'!$B:$B,0)),0,I32*INDEX('1. Assumptions'!$G:$G,MATCH("Growth Monthly Churn",'1. Assumptions'!$B:$B,0))) -> 5.3944783 | J36: =IF(J5<INDEX('1. Assumptions'!$G:$G,MATCH("Churn Start Month",'1. Assumptions'!$B:$B,0)),0,J32*INDEX('1. Assumptions'!$G:$G,MATCH("Growth Monthly Churn",'1. Assumptions'!$B:$B,0))) -> 5.5932116 | K36: =IF(K5<INDEX('1. Assumptions'!$G:$G,MATCH("Churn Start Month",'1. Assumptions'!$B:$B,0)),0,K32*INDEX('1. Assumptions'!$G:$G,MATCH("Growth Monthly Churn",'1. Assumptions'!$B:$B,0))) -> 5.8073356 | ... AA36: =IF(AA5<INDEX('1. Assumptions'!$G:$G,MATCH("Churn Start Month",'1. Assumptions'!$B:$B,0)),0,AA32*INDEX('1. Assumptions'!$G:$G,MATCH("Growth Monthly Churn",'1. Assumptions'!$B:$B,0))) -> 12.992423
A37: Growth Customers | B37: Ending Growth Customers | C37: Customers | D37: =D32+D33+D34-D35-D36 -> 189.55 | E37: =E32+E33+E34-E35-E36 -> 195.29738 | F37: =F32+F33+F34-F35-F36 -> 201.5839 | G37: =G32+G33+G34-G35-G36 -> 208.40666 | H37: =H32+H33+H34-H35-H36 -> 215.77913 | I37: =I32+I33+I34-I35-I36 -> 223.72846 | J37: =J32+J33+J34-J35-J36 -> 232.29342 | K37: =K32+K33+K34-K35-K36 -> 241.52297 | ... AA37: =AA32+AA33+AA34-AA35-AA36 -> 553.55241 | AC37: Beginning + New + Starter Upgrades - Enterprise Upgrades - Churn
A39: § 6 ENTERPRISE CUSTOMER ROLL-FORWARD
A40: Enterprise Customers | B40: Beginning Enterprise Customers | C40: Customers | D40: =INDEX('1. Assumptions'!$G:$G,MATCH("Starting Enterprise Customers",'1. Assumptions'!$B:$B,0)) -> 0 | E40: =D44 -> 0.45 | F40: =E44 -> 0.91782162 | G40: =F44 -> 1.3937186 | H40: =G44 -> 1.8789301 | I40: =H44 -> 2.3746715 | J40: =I44 -> 3.8821753 | K40: =J44 -> 5.4592737 | L40: =K44 -> 7.1114694 | ... AA40: =Z44 -> 46.21598
